Workbook

Sheet Company Info
B1: Organizational Profile: Surf Corporation | D1: Sector: | E1: Consumer Products
B3: Company Overview:
B4: Orginally founded in 1947 as the Surfactant Chemical Company, today Surf Corporation is a global consumer products company headquartered in Easton, Delaware providing personal and home cleaning products in over 100 countries.
B5: Annual Revenue: | C5: $10.8B USD
B6: Company Values: | C6: All We Do is based on our belief in: Quality Products - Healthier Lives - Responsible Growth
B7: Sustainability Strategic Framework: | C7: Growth - Health - Environment
B8: Sustainability Culture: | C8: Long-standing CSR programs focused on community outreach and health. Minimal environmental programs beyond regulatory compliance and facility energy reduction.
B9: Key Sustainability Risks: | C9: Water: all products require use of water to formulate, manufacture and use
B10: Key Sustainability Drivers: | C10: Increased awareness and interest by the company's main customers and consumers, as well as NGO and investor inquiries has increased the profile of sustainability with the company's Board of Directors and Senior Management team.
B12: General Operational Data
B13: # full time employees | C13: 22000
B14: Annual Production | C14: Approx. 3.5M metric tonnes
B15: # manufacturing facilities | C15: 18
B16: Facilities owned (sq feet) | C16: 7500000 | E16: =2941*22000 -> 64702000
B17: Facilities leased (sq feet) | C17: 2500000
B18: Percent of In-House Manufacturing | C18: 0.95
B19: Commute | C19: Survey shows each employee commutes an average of 2,941 miles in a year (passenger car as mode of transportation assumed)
B20: Indirect emissions coming from fuel and energy-related activities account for approximately 10% of the total of scope 1 and 2 emissions combined.
B21: Annual investment in capital goods and other building equipment | C21: $1B
B22: Purchased Goods & Services (spend in USD): | E22: Emissions Factors (EFs)
B23: - Chemical Raw Materials (Petrochemicals) | C23: 1200000000 | D23: USD | E23: 1.164 | F23: kgCO2e/USD
B24: - Machinary (Indusr Machines & Equip) | C24: 100000000 | D24: USD | E24: 0.117 | F24: kgCO2e/USD
B25: - Real Estate | C25: 20000000 | D25: USD | E25: e | F25: kgCO2e/USD
B26: Business Travel: Air and Car | E26: Emissions Factors (EFs)
B27: - Air Travel | C27: 45000000 | D27: miles | E27: 0.16394667 | F27: kgCO2e/mile
B28: - Car Travel | C28: 2830000 | D28: miles | E28: 0.30798587 | F28: kgCO2e/mile
B29: Annual Energy Usage
B30: Natural Gas | C30: 12010199 | D30: m3/yr
B31: Diesel Fuel | C31: 1392598 | D31: litres/yr
B32: Electricity - by country
B33: China | C33: 150500 | D33: MWh/yr
B34: Mexico | C34: 215000 | D34: MWh/yr
B35: USA (Texas) | C35: 50500 | D35: MWh/yr
B36: France | C36: 179500 | D36: MWh/yr
B37: South Africa | C37: 45500 | D37: MWh/yr
B38: * Indirect emissions coming from fuel and energy-related activities account for approximately 10% of the total of scope 1 and 2 emissions combined.
B39: General Product Portfolio Mix | C39: Consumer Use Volume | E39: Emission Factors (EF) kgCO2e/MT
B40: Soap & Shampoo | C40: 1750000 | D40: MT/yr | E40: 0.353 | F40: MT CO2e/MT product
B41: Laundry Detergent | C41: 1050000 | D41: MT/yr | E41: 0.2829 | F41: MT CO2e/MT product
B42: Dish Soap | C42: 650000 | D42: MT/yr | E42: 0.504 | F42: MT CO2e/MT product
...

Sheet Scope 1 & 2 GHG Factors
A1: Direct Emissions factors from Fuel Usage (Scope 1)
A2: Energy Type (unit) | B2: CO2 Factor (kg CO2e/unit)
A3: Anthracite Coal (kg) | B3: 2.64322
A4: Bituminous Coal (kg) | B4: 2.45866
A5: Diesel Oil (litres) | B5: 2.68566
A6: LPG (kg) | B6: 2.98722
A7: LPG (litres) | B7: 1.6131
A8: Natural Gas (m3) | B8: 1.8868
A9: Residual Oil (litres) | B9: 2.94898
A10: Steam (kWh) | B10: 189.74
A13: Indirect Emissions factors by Country from Purchased Electricity (Scope 2) - CO2e per MWh of electricity
A15: Country/ Region | B15: 2017 | C15: 2018 | D15: 2019 | E15: 2020 | F15: 2021 | G15: 2022
A16: Argentina | B16: 362.6981 | C16: 366.9635 | D16: =C16 -> 366.9635 | E16: =D16 -> 366.9635 | F16: =E16 -> 366.9635 | G16: =F16*0.96 -> 352.28496
A17: Australia | B17: 852.2029 | C17: 840.9243 | D17: =C17 -> 840.9243 | E17: =D17 -> 840.9243 | F17: =E17 -> 840.9243 | G17: =F17*0.96 -> 807.28733
A18: Belgium | B18: 217.9705 | C18: 219.5577 | D18: =C18 -> 219.5577 | E18: =D18 -> 219.5577 | F18: =E18 -> 219.5577 | G18: =F18*0.96 -> 210.77539
A19: Brazil | B19: 64.3512 | C19: 86.7654 | D19: =C19 -> 86.7654 | E19: =D19 -> 86.7654 | F19: =E19 -> 86.7654 | G19: =F19*0.96 -> 83.294784
A20: Cameroon | B20: 196.2359 | C20: 207.1761 | D20: =C20 -> 207.1761 | E20: =D20 -> 207.1761 | F20: =E20 -> 207.1761 | G20: =F20*0.96 -> 198.88906
A21: Canada | B21: 176.3732 | C21: 186.4102 | D21: =C21 -> 186.4102 | E21: =D21 -> 186.4102 | F21: =E21 -> 186.4102 | G21: =F21*0.96 -> 178.95379
A22: Chile | B22: 373.448 | C22: 409.6667 | D22: =C22 -> 409.6667 | E22: =D22 -> 409.6667 | F22: =E22 -> 409.6667 | G22: =F22*0.96 -> 393.28003
A23: China | B23: 799.9253 | C23: 766.0941 | D23: =C23 -> 766.0941 | E23: =D23 -> 766.0941 | F23: =E23 -> 766.0941 | G23: =F23*0.96 -> 735.45034
A24: Colombia | B24: 175.5043 | C24: 175.737 | D24: =C24 -> 175.737 | E24: =D24 -> 175.737 | F24: =E24 -> 175.737 | G24: =F24*0.96 -> 168.70752
A25: Costa Rica | B25: 39.7213 | C25: 55.7064 | D25: =C25 -> 55.7064 | E25: =D25 -> 55.7064 | F25: =E25 -> 55.7064 | G25: =F25*0.96 -> 53.478144
A26: Czech Republic | B26: 588.2133 | C26: 589.0224 | D26: =C26 -> 589.0224 | E26: =D26 -> 589.0224 | F26: =E26 -> 589.0224 | G26: =F26*0.96 -> 565.4615
A27: Denmark | B27: 398.3116 | C27: 359.6725 | D27: =C27 -> 359.6725 | E27: =D27 -> 359.6725 | F27: =E27 -> 359.6725 | G27: =F27*0.96 -> 345.2856
... A63: United Kingdom | B63: 453.4799 | C63: 457.3677 | D63: =C63 -> 457.3677 | E63: =D63 -> 457.3677 | F63: =E63 -> 457.3677 | G63: =F63*0.96 -> 439.07299
A64: United States eGRID regions
A65: SRSO - Georgia | B65: 604.45442 | C65: =B65 -> 604.45442 | D65: =C65 -> 604.45442 | E65: =D65 -> 604.45442 | F65: =E65 -> 604.45442 | G65: =F65*0.96 -> 580.27624
A66: SRTV | B66: 619.11817 | C66: =B66 -> 619.11817 | D66: =C66 -> 619.11817 | E66: =D66 -> 619.11817 | F66: =E66 -> 619.11817 | G66: =F66*0.96 -> 594.35344
A67: RFCE | B67: 432.10426 | C67: =B67 -> 432.10426 | D67: =C67 -> 432.10426 | E67: =D67 -> 432.10426 | F67: =E67 -> 432.10426 | G67: =F67*0.96 -> 414.82009
A68: RFCW - Ohio | B68: 693.43692 | C68: =B68 -> 693.43692 | D68: =C68 -> 693.43692 | E68: =D68 -> 693.43692 | F68: =E68 -> 693.43692 | G68: =F68*0.96 -> 665.69944
A69: NYCW | B69: 277.61582 | C69: =B69 -> 277.61582 | D69: =C69 -> 277.61582 | E69: =D69 -> 277.61582 | F69: =E69 -> 277.61582 | G69: =F69*0.96 -> 266.51119
A70: ERCT - Texas | B70: 538.02478 | C70: =B70 -> 538.02478 | D70: =C70 -> 538.02478 | E70: =D70 -> 538.02478 | F70: =E70 -> 538.02478 | G70: =F70*0.96 -> 516.50379
A71: SPNO - Kansas | B71: 827.87719 | C71: =B71 -> 827.87719 | D71: =C71 -> 827.87719 | E71: =D71 -> 827.87719 | F71: =E71 -> 827.87719 | G71: =F71*0.96 -> 794.7621
A72: RFCE | B72: 432.10426 | C72: =B72 -> 432.10426 | D72: =C72 -> 432.10426 | E72: =D72 -> 432.10426 | F72: =E72 -> 432.10426 | G72: =F72*0.96 -> 414.82009
A73: SPNO | B73: 827.87719 | C73: =B73 -> 827.87719 | D73: =C73 -> 827.87719 | E73: =D73 -> 827.87719 | F73: =E73 -> 827.87719 | G73: =F73*0.96 -> 794.7621
A74: CAMX | B74: 299.91726 | C74: =B74 -> 299.91726 | D74: =C74 -> 299.91726 | E74: =D74 -> 299.91726 | F74: =E74 -> 299.91726 | G74: =F74*0.96 -> 287.92057
A75: SRTV | B75: 619.11817 | C75: =B75 -> 619.11817 | D75: =C75 -> 619.11817 | E75: =D75 -> 619.11817 | F75: =E75 -> 619.11817 | G75: =F75*0.96 -> 594.35344
A76: NEWE | B76: 333.07014 | C76: =B76 -> 333.07014 | D76: =C76 -> 333.07014 | E76: =D76 -> 333.07014 | F76: =E76 -> 333.07014 | G76: =F76*0.96 -> 319.74734
... A78: SPNO | B78: 827.87719 | C78: =B78 -> 827.87719 | D78: =C78 -> 827.87719 | E78: =D78 -> 827.87719 | F78: =E78 -> 827.87719 | G78: =F78*0.96 -> 794.7621
A79: FRCC-Florida | G79: 461.031
...

Sheet GHG Calc
A1: Scope 1,2,3 GHG Emissions Calculations Sheet
A2: Scope 1 | B2: Manufacturing Facility Fuel Usage
B3: Natural gas | C3: ='[1]General Company Info'!C30 -> 12010199 | D3: m3/yr | E3: Emission Factors (EF) | F3: Calculated CO2e Emissions (kg) | G3: Calculated CO2e Emissions (MT)
B4: Diesel fuel | C4: ='[1]General Company Info'!C31 -> 1392598 | D4: litres/yr | E4: ='[1]Scope 1 & 2 GHG Factors'!B8 -> 1.8868 | F4: =C3*E4 -> 22660843 | G4: =F4/1000 -> 22660.843
E5: ='[1]Scope 1 & 2 GHG Factors'!B5 -> 2.68566 | F5: =C4*E5 -> 3740044.7 | G5: =F5/1000 -> 3740.0447
A6: Scope 2 | B6: Manufacturing Facility Electricity Usage | G6: =G4+G5 -> 26400.888 | H6: Total Scope 1
B7: Electricity Use - by country | E7: Emission Factors (EF) | F7: Calculated CO2e Emissions (kg) | G7: Calculated CO2e Emissions (MT)
B8: China | C8: ='[1]General Company Info'!C33 -> 150500 | D8: MWh/yr
B9: Mexico | C9: ='[1]General Company Info'!C34 -> 215000 | D9: MWh/yr | E9: ='[1]Scope 1 & 2 GHG Factors'!G23 -> 735.45034 | F9: =E9*C8 -> 1.1068528e+08 | G9: =F9/1000 -> 110685.28
B10: USA (Texas) | C10: ='[1]General Company Info'!C35 -> 50500 | D10: MWh/yr | E10: ='[1]Scope 1 & 2 GHG Factors'!G43 -> 436.64074 | F10: =E10*C9 -> 93877758 | G10: =F10/1000 -> 93877.758
B11: France | C11: ='[1]General Company Info'!C36 -> 179500 | D11: MWh/yr | E11: ='[1]Scope 1 & 2 GHG Factors'!G70 -> 516.50379 | F11: =E11*C10 -> 26083442 | G11: =F11/1000 -> 26083.442
B12: South Africa | C12: ='[1]General Company Info'!C37 -> 45500 | D12: MWh/yr | E12: ='[1]Scope 1 & 2 GHG Factors'!G31 -> 75.928416 | F12: =E12*C11 -> 13629151 | G12: =F12/1000 -> 13629.151
E13: ='[1]Scope 1 & 2 GHG Factors'!G57 -> 889.47533 | F13: =E13*C12 -> 40471127 | G13: =F13/1000 -> 40471.127
A14: Scope 3 - Cat 1 | B14: Purchased Goods & Services | G14: =SUM(G9:G13) -> 284746.75 | H14: Total Scope 2
B15: Chem Raw Materials (Petro) | C15: ='[1]General Company Info'!C23 -> 1200000000 | D15: USD | E15: Emission Factors (EF) | F15: Calculated CO2e Emissions (kg) | G15: Calculated CO2e Emissions (MT)
B16: Machinary | C16: ='[1]General Company Info'!C24 -> 100000000 | D16: USD | E16: ='[1]General Company Info'!E23 -> 1.164 | F16: =E16*C15 -> 1396800000 | G16: =F16/1000 -> 1396800
B17: Real Estate | C17: ='[1]General Company Info'!C25 -> 20000000 | D17: USD | E17: ='[1]General Company Info'!E24 -> 0.117 | F17: =E17*C16 -> 11700000 | G17: =F17/1000 -> 11700
E18: ='[1]General Company Info'!E25 -> 0.086 | F18: =E18*C17 -> 1720000 | G18: =F18/1000 -> 1720
A19: Scope 3 - Cat 3 | B19: Fuel/Energy Activities | G19: =SUM(G16:G18) -> 1410220 | H19: Scope 3, Cat 1
B20: Assumes additional 10% emissions based on total Scope 1 & 2 emissions
B21: Scope 1 | C21: =G6 -> 26400.888 | D21: MT
B22: Scope 2 | C22: =G14 -> 284746.75 | D22: MT
B23: Total | C23: =C21+C22 -> 311147.64 | D23: MT
E24: 0.1 | F24: factor
A25: Scope 3 - Cat 6 | B25: Business Travel | G25: =C23*E24 -> 31114.764 | H25: Scope 3, Cat 3
B26: Air Travel | C26: ='[1]General Company Info'!C27 -> 45000000 | D26: miles | E26: Emissions Factors (EFs) kgCO2e/mile | F26: Calculated CO2e Emissions (kg) | G26: Calculated CO2e Emissions (MT)
B27: Car Travel | C27: ='[1]General Company Info'!C28 -> 2830000 | D27: miles | E27: ='[1]General Company Info'!E27 -> 0.16394667 | F27: =E27*C26 -> 7377600 | G27: =F27/1000 -> 7377.6
E28: ='[1]General Company Info'!E28 -> 0.30798587 | F28: =E28*C27 -> 871600 | G28: =F28/1000 -> 871.6
A29: Scope 3 - Cat 11 | B29: General Product Portfolio Mix* | C29: Consumer Use Volume | G29: =G27+G28 -> 8249.2 | H29: Scope 3, Cat 6
B30: Soap & Shampoo | C30: ='[1]General Company Info'!C40 -> 1750000 | D30: MT/yr | E30: Emission Factors (EF) MTCO2e/MT product | G30: Calculated CO2e Emissions (MT)
B31: Laundry Detergent | C31: ='[1]General Company Info'!C41 -> 1050000 | D31: MT/yr | E31: ='[1]General Company Info'!E40 -> 0.353 | G31: =E31*C30 -> 617750
B32: Dish Soap | C32: ='[1]General Company Info'!C42 -> 650000 | D32: MT/yr | E32: ='[1]General Company Info'!E41 -> 0.2829 | G32: =E32*C31 -> 297045
B33: Floor Cleaner | C33: ='[1]General Company Info'!C43 -> 250000 | D33: MT/yr | E33: ='[1]General Company Info'!E42 -> 0.504 | G33: =E33*C32 -> 327600
E34: ='[1]General Company Info'!E43 -> 2.828 | G34: =E34*C33 -> 707000
G35: =SUM(G31:G34) -> 1949395 | H35: Scope 3, Cat 11
B36: *Use product protfolio mix values for use of sold products calculations

Sheet Overall
A1: CO2 by Category | B1: CO2 by Category | C1: CO2 by Category
A2: Scope 3 Total | B2: =SUM(B5:B8) -> 3398979 | C2: =+B2/B9 -> 0.91613557
A3: Scope 1 | B3: ='GHG Calc'!G6 -> 26400.888 | C3: =+B3/$B$9 -> 0.0071158995
A4: Scope 2 | B4: ='GHG Calc'!G14 -> 284746.75 | C4: =+B4/$B$9 -> 0.076748527
A5: Category 1 - Purchased Goods/Svc | B5: ='GHG Calc'!G19 -> 1410220 | C5: =+B5/$B$9 -> 0.38010024
A6: Category 3 - Fuel/Energy Related Activities | B6: ='GHG Calc'!G25 -> 31114.764 | C6: =+B6/$B$9 -> 0.0083864427
A7: Category 6 - Business Travel | B7: ='GHG Calc'!G29 -> 8249.2 | C7: =+B7/$B$9 -> 0.0022234282
A8: Category 11 - Use of Sold Products | B8: ='GHG Calc'!G35 -> 1949395 | C8: =+B8/$B$9 -> 0.52542547
A9: Total emissions | B9: =SUM(B3:B8) -> 3710126.6
